<!-- AMBER 2D Model Description                                         -->
<robot name="human_PF_adjustable">
  <material name="red">
    <color rgba="0 0 0.8 1"/>
  </material>

  <!-- Linkage Definitions -->
  <link name="Torso">
    <inertial>
      <origin xyz="0 0 -0.28507"/>
      <mass value="13"/>
      <inertia ixx="0" ixy="0" ixz="0" iyy="0.1940" iyz="0" izz="0"/>
    </inertial>
  </link>
  <link name="LeftThighUpper">
    <inertial>
      <origin xyz="0.0 0.0 -0.1" rpy= "0 0 0"/>
      <mass value="1.7"/>
      <inertia ixx="0" ixy="0" ixz="0" iyy="0.006" iyz="0" izz="0"/>
    </inertial>
  </link>
  <link name="LeftThighLower">
    <inertial>
      <origin xyz="0.0 0.0 -0.1" rpy= "0 0 0"/>
      <mass value="1.7"/>
      <inertia ixx="0" ixy="0" ixz="0" iyy="0.006" iyz="0" izz="0"/>
    </inertial>
  </link>
  <link name="LeftShinUpper">
    <inertial>
      <origin xyz="0 0 -0.1" rpy="0 0 0"/>
      <mass value="0.4250"/>
      <inertia ixx="0" ixy="0" ixz="0" iyy="0.0015" iyz="0" izz="0"/>
    </inertial>
  </link>
  <link name="LeftShinLower">
    <inertial>
      <origin xyz="0 0 -0.1" rpy="0 0 0"/>
      <mass value="0.4250"/>
      <inertia ixx="0" ixy="0" ixz="0" iyy="0.0015" iyz="0" izz="0"/>
    </inertial>
  </link>
  <link name="RightThighUpper">
    <inertial>
      <origin xyz="0.0 0.0 -0.1" rpy= "0 0 0"/>
      <mass value="1.7"/>
      <inertia ixx="0" ixy="0" ixz="0" iyy="0.006" iyz="0" izz="0"/>
    </inertial>
  </link>
  <link name="RightThighLower">
    <inertial>
      <origin xyz="0.0 0.0 -0.1" rpy= "0 0 0"/>
      <mass value="1.7"/>
      <inertia ixx="0" ixy="0" ixz="0" iyy="0.006" iyz="0" izz="0"/>
    </inertial>
  </link>
  <link name="RightShinUpper">
    <inertial>
      <origin xyz="0 0 -0.1" rpy="0 0 0"/>
      <mass value="0.4250"/>
      <inertia ixx="0" ixy="0" ixz="0" iyy="0.0015" iyz="0" izz="0"/>
    </inertial>
  </link>
  <link name="RightShinLower">
    <inertial>
      <origin xyz="0 0 -0.1" rpy="0 0 0"/>
      <mass value="0.4250"/>
      <inertia ixx="0" ixy="0" ixz="0" iyy="0.0015" iyz="0" izz="0"/>
    </inertial>
  </link>


  <!-- Joint Definitions -->
  <joint name="LeftHip" type="revolute">
    <parent link="Torso"/>
    <child link="LeftThighUpper"/>
    <origin xyz="0 0 -0.4999" rpy="0 0 0"/>
    <axis xyz="0 1 0"/>
    <limit effort="400.0" lower="-1.6" upper="1.6" velocity="4"/>
  </joint>
  <joint name="LeftThighExtension" type="prismatic">
    <axis xyz="0 0 -1"/>
    <limit effort="1000.0" lower="-0.4" upper="0.4" velocity="1000"/>
    <origin rpy="0 0 0" xyz="0 0 -0.2"/>
    <parent link="LeftThighUpper"/>
    <child link="LeftThighLower"/>
  </joint>
  <joint name="LeftKnee" type="revolute">
    <parent link="LeftThighLower"/>
    <child link="LeftShinUpper"/>
    <origin xyz="0.0 0.0 -0.2" rpy="0 0 0"/>
    <axis xyz="0 1 0"/>
    <limit effort="400.0" lower="0.1" upper="1.5" velocity="4"/>
  </joint>
  <joint name="LeftShinExtension" type="prismatic">
    <axis xyz="0 0 -1"/>
    <limit effort="1000.0" lower="-0.4" upper="0.4" velocity="1000"/>
    <origin rpy="0 0 0" xyz="0 0 -0.2"/>
    <parent link="LeftShinUpper"/>
    <child link="LeftShinLower"/>
  </joint>
    <joint name="RightHip" type="revolute">
    <parent link="Torso"/>
    <child link="RightThighUpper"/>
    <origin xyz="0.0 0.0 -0.4999" rpy="0 0 0"/>
    <axis xyz="0 1 0"/>
    <limit effort="400.0" lower="-1.6" upper="1.6" velocity="4"/>
  </joint>
  <joint name="RightThighExtension" type="prismatic">
    <axis xyz="0 0 -1"/>
    <limit effort="1000.0" lower="-0.4" upper="0.4" velocity="1000"/>
    <origin rpy="0 0 0" xyz="0 0 -0.2"/>
    <parent link="RightThighUpper"/>
    <child link="RightThighLower"/>
  </joint>
  <joint name="RightKnee" type="revolute">
    <parent link="RightThighLower"/>
    <child link="RightShinUpper"/>
    <origin xyz="0.0 0.0 -0.2" rpy="0 0 0"/>
    <axis xyz="0 1 0"/>
    <limit effort="400.0" lower="0.1" upper="1.5" velocity="4"/>
  </joint>
  <joint name="RightShinExtension" type="prismatic">
    <axis xyz="0 0 -1"/>
    <limit effort="1000.0" lower="-0.4" upper="0.4" velocity="1000"/>
    <origin rpy="0 0 0" xyz="0 0 -0.2"/>
    <parent link="RightShinUpper"/>
    <child link="RightShinLower"/>
  </joint>

  
  <!-- Robot Transmission Definitions -->
  <transmission name="LeftHipTransmission">
    <joint name="LeftHip"/>
    <actuator>
      <mechanicalReduction>91.4286</mechanicalReduction>
      <motorInertia>0.000051</motorInertia>
    </actuator>
  </transmission>
  <transmission name="LeftThighExtensionTransmission">
    <type>transmission_interface/SimpleTransmission</type>
    <joint name="LeftThighExtension">
      <hardwareInterface>EffortJointInterface</hardwareInterface>
    </joint>
    <actuator name="LeftThighExtension">
      <mechanicalReduction>1000</mechanicalReduction>
    </actuator>
  </transmission>  
  <transmission name="LeftKneeTransmission">
    <joint name="LeftKnee"/>
    <actuator>
      <mechanicalReduction>91.4286</mechanicalReduction>
      <motorInertia>0.000051</motorInertia>
    </actuator>
  </transmission>
  <transmission name="LeftShinExtensionTransmission">
    <type>transmission_interface/SimpleTransmission</type>
    <joint name="LeftShinExtension">
      <hardwareInterface>EffortJointInterface</hardwareInterface>
    </joint>
    <actuator name="LeftShinExtension">
      <mechanicalReduction>1000</mechanicalReduction>
    </actuator>
  </transmission> 
  <transmission name="RightHipTransmission">
    <joint name="RightHip"/>
    <actuator>
      <mechanicalReduction>91.4286</mechanicalReduction>
      <motorInertia>0.000051</motorInertia>
    </actuator>
  </transmission>
  <transmission name="RightThighExtensionTransmission">
    <type>transmission_interface/SimpleTransmission</type>
    <joint name="RightThighExtension">
      <hardwareInterface>EffortJointInterface</hardwareInterface>
    </joint>
    <actuator name="RightThighExtension">
      <mechanicalReduction>1000</mechanicalReduction>
    </actuator>
  </transmission>  
  <transmission name="RightKneeTransmission">
    <joint name="RightKnee"/>
    <actuator>
      <mechanicalReduction>91.4286</mechanicalReduction>
      <motorInertia>0.000051</motorInertia>
    </actuator>
  </transmission>
  <transmission name="RightShinExtensionTransmission">
    <type>transmission_interface/SimpleTransmission</type>
    <joint name="RightShinExtension">
      <hardwareInterface>EffortJointInterface</hardwareInterface>
    </joint>
    <actuator name="RightShinExtension">
      <mechanicalReduction>1000</mechanicalReduction>
    </actuator>
  </transmission> 
</robot>
